<robot name="mk_station" version="1.0">
  <joint name="top_drawer_joint" type="prismatic">
    <limit lower="0" upper="0.5" effort="10.0" velocity="1.0"/>
    <origin rpy="0.00000 0.00000 0.00000" xyz="0.00000 0.00000 0.55000"/>
    <parent link="body"/>
    <child link="top_drawer"/>
    <axis xyz="1.00000 0.00000 0.00000"/>
  </joint>
  
  <joint name="bottom_drawer_joint" type="prismatic">
    <limit lower="0" upper="0.5" effort="10.0" velocity="1.0"/>
    <origin rpy="0.00000 0.00000 0.00000" xyz="0.00000 0.00000 0.25000"/>
    <parent link="body"/>
    <child link="bottom_drawer"/>
    <axis xyz="1.00000 0.00000 0.00000"/>
  </joint>

  <link name="body">
    <collision name="body_back_collision">
      <origin rpy="0.00000 0.00000 0.00000" xyz="-0.30500 0.00000 0.40000"/>
      <geometry>
        <box size="0.02000 0.61500 0.80000"/>
      </geometry>
    </collision>
    <visual name="body_back">
      <origin rpy="0.00000 0.00000 0.00000" xyz="-0.30500 0.00000 0.40000"/>
      <material name="gray_wooden"/>
      <geometry>
        <box size="0.02000 0.61500 0.80000"/>
      </geometry>
    </visual>

    <collision name="tabletop_collision">
      <origin rpy="0.00000 0.00000 0.00000" xyz="0.00000 0.00000 0.80000"/>
      <geometry>
        <box size="0.63000 0.61500 0.02000"/>
      </geometry>
    </collision>
    <visual name="tabletop">
      <origin rpy="0.00000 0.00000 0.00000" xyz="0.00000 0.00000 0.80000"/>
      <geometry>
        <mesh filename="models/stone_tabletop.glb"/>
      </geometry>
    </visual>
  </link>

  <link name="top_drawer">
    <visual name="handle">
      <origin rpy="0.00000 0.00000 0.00000" xyz="0.34250 0.00000 0.02"/>
      <material name="black"/>
      <geometry>
        <box size="0.005000 0.10000 0.00500"/>
      </geometry>
    </visual>
    <collision name="drawer_front_collision">
      <origin rpy="0.00000 0.00000 0.00000" xyz="0.30500 0.00000 0.0"/>
      <geometry>
        <box size="0.015000 0.61500 0.14000"/>
      </geometry>
    </collision>
    <visual name="drawer_front">
      <origin rpy="0.00000 0.00000 0.00000" xyz="0.30500 0.00000 0.0"/>
      <material name="gray_wooden"/>
      <geometry>
        <box size="0.015000 0.61500 0.14000"/>
      </geometry>
    </visual>
  </link>

  <link name="bottom_drawer">
    <visual name="handle">
      <origin rpy="0.00000 0.00000 0.00000" xyz="0.34250 0.00000 0.02"/>
      <material name="black"/>
      <geometry>
        <box size="0.005000 0.10000 0.00500"/>
      </geometry>
    </visual>
    <collision name="drawer_front_collision">
      <origin rpy="0.00000 0.00000 0.00000" xyz="0.30500 0.00000 0.0"/>
      <geometry>
        <box size="0.015000 0.61500 0.14000"/>
      </geometry>
    </collision>
    <visual name="drawer_front">
      <origin rpy="0.00000 0.00000 0.00000" xyz="0.30500 0.00000 0.0"/>
      <material name="gray_wooden"/>
      <geometry>
        <box size="0.015000 0.61500 0.14000"/>
      </geometry>
    </visual>
  </link>

  <material name="gray_wooden">
    <color rgba="0.325 0.187 0.1166 1.0"/>
  </material>
  <material name="red">
    <color rgba="0.01266 0.00226 0.0005 1.00000"/>
  </material>
</robot>
